Workbook

Sheet Overview
B1: Weekly Dashboard — March 25, 2026
B2: Ashwin Conrad | Engineering Co-op Student | AltaGas Ltd.
B4: Project Status Summary
B5: Project | C5: Category | D5: Status | E5: Priority | F5: Active Tasks | G5: % Complete | H5: Allocated (hrs) | I5: Spent (hrs)
B6: Safety Critical Element (SCE) Identification | C6: Weekly | D6: In Progress | E6: P1 – Urgent | F6: 3 | G6: 9/21 | H6: — | I6: —
B7: Brazed Aluminum Heat Exchanger (BAHX) Study | C7: Weekly | D7: In Progress | E7: P1 – Urgent | F7: 4 | G7: 7/19 | H7: — | I7: —
B8: Corrosion Coupon Dashboard | C8: Ongoing | D8: In Progress | E8: P2 – High | F8: 2 | G8: 4/13 | H8: — | I8: —
B9: Inspection Scope Tool | C9: Ongoing | D9: In Progress | E9: P2 – High | F9: 1 | G9: 4/8 | H9: — | I9: —
B10: PI Vision Screen Cleanup | C10: Ongoing | D10: Ongoing | E10: P5 – Background | F10: 1 | G10: 0/3 | H10: — | I10: —
B11: AI & Python Workflow Automation | C11: Ongoing | D11: Ongoing | E11: P5 – Background | F11: 1 | G11: 0/3 | H11: — | I11: —
B13: Weekly Schedule
B14: Priority | C14: Wed 03/25 | D14: Thu 03/26 | E14: Fri 03/27 | F14: Sat 03/28 | G14: Sun 03/29 | H14: Mon 03/30 | I14: Tue 03/31
B15: P1 – Urgent | C15: SCE Identification - Harmattan & EEEP | D15: BAHX Final Report
B16: P2 – High | C16: Maximo Tag Matching | D16: BAHX Vendor Meeting - April 1 | E16: BAHX Presentation | F16: SCE Site Review Meetings | G16: Auto-Triggered Email Data Pipeline
B17: P3 – Medium | C17: BAHX SOP Review | D17: Inspection Scope Tool - Handoff Documentation | E17: Corrosion Dashboard Handoff Documentation
B18: P4 – Low
B19: P5 – Background | C19: AI & Python Applications - Exploration & Prototyping | D19: PI Vision Screen Cleanup - Units, Tags, and Navigation
B21: Time Overview
B22: Project | C22: Allocated (hrs) | D22: Spent (hrs) | E22: Remaining (hrs) | F22: Utilization %
B23: Safety Critical Element (SCE) Identification | C23: — | D23: — | E23: — | F23: —
B24: Brazed Aluminum Heat Exchanger (BAHX) Study | C24: — | D24: — | E24: — | F24: —
B25: Corrosion Coupon Dashboard | C25: — | D25: — | E25: — | F25: —
B26: Inspection Scope Tool | C26: — | D26: — | E26: — | F26: —
B27: PI Vision Screen Cleanup | C27: — | D27: — | E27: — | F27: —
B28: AI & Python Workflow Automation | C28: — | D28: — | E28: — | F28: —
B29: TOTAL | C29: — | D29: — | E29: — | F29: —
B31: Upcoming Deadlines (Next 14 Days)
B32: Deadline | C32: Item | D32: Status | E32: Parent
B33: 2026-03-25 | C33: Complete SCE identification for Harmattan | D33: In Progress | E33: SCE Identification - Harmattan & EEEP
B34: 2026-03-25 | C34: Investigate and resolve unmatched tags (~55% remaining) | D34: In Progress | E34: Maximo Tag Matching
B35: 2026-03-25 | C35: Outline presentation structure and key messages | D35: In Progress | E35: BAHX Presentation
B36: 2026-03-28 | C36: Draft report - recommendations and action plan | D36: In Progress | E36: BAHX Final Report
B37: 2026-03-28 | C37: Prepare BAHX unit specs and questions for vendor | D37: In Progress | E37: BAHX Vendor Meeting - April 1
B38: 2026-03-31 | C38: SCE Identification - Harmattan & EEEP | D38: In Progress | E38: Safety Critical Element (SCE) Identification
B39: 2026-03-31 | C39: Complete SCE identification for EEEP | D39: In Progress | E39: SCE Identification - Harmattan & EEEP
B40: 2026-03-31 | C40: Maximo Tag Matching | D40: In Progress | E40: Safety Critical Element (SCE) Identification
B41: 2026-03-31 | C41: Produce final Maximo match report with gap summary | D41: Not Started | E41: Maximo Tag Matching
B42: 2026-04-01 | C42: BAHX Vendor Meeting - April 1 | D42: In Progress | E42: Brazed Aluminum Heat Exchanger (BAHX) Study
B43: 2026-04-01 | C43: Attend vendor meeting and capture notes | D43: Not Started | E43: BAHX Vendor Meeting - April 1
... B47: 2026-04-07 | C47: Write technical documentation - code architecture and logic | D47: Not Started | E47: Inspection Scope Tool - Handoff Documentation

Sheet Projects
A1: Project ID | B1: Title | C1: Category | D1: Supervisor | E1: Site | F1: Description | G1: Status | H1: Priority | I1: Start Date | J1: End Date | K1: Deadline | L1: Date Completed | M1: Notes
A2: P-001 | B2: Safety Critical Element (SCE) Identification | C2: Weekly | F2: Identify and catalog Safety Critical Elements across all AltaGas facilities by cross-referencing P&IDs, SDKs, and Maximo asset databases. | G2: In Progress | H2: 0 | I2: 45689 | K2: 46112
A3: P-002 | B3: Brazed Aluminum Heat Exchanger (BAHX) Study | C3: Weekly | F3: Technical study evaluating the condition, risk profile, and replacement strategy for BAHX units across AltaGas facilities. | G3: In Progress | H3: 0 | I3: 45962 | K3: 46157
A4: P-003 | B4: Corrosion Coupon Dashboard | C4: Ongoing | F4: Power BI dashboard tracking corrosion coupon data across all AltaGas facilities. | G4: In Progress | H4: 0 | I4: 45901 | K4: 46265
A5: P-004 | B5: Inspection Scope Tool | C5: Ongoing | F5: Python tool that assists with the creation of inspection scopes. Tool is complete and deployed; handoff documentation required. | G5: In Progress | H5: 0 | I5: 45809 | K5: 46142
A6: P-005 | B6: PI Vision Screen Cleanup | C6: Ongoing | F6: Long-term, background cleanup effort to improve PI Vision usability and pave the way for enterprise-wide PI screen standardization. | G6: Ongoing | H6: 0
A7: P-006 | B7: AI & Python Workflow Automation | C7: Ongoing | F7: Self-directed initiative exploring AI and Python tools for engineering workflow automation and operational optimization. | G7: Ongoing | H7: 0

Sheet Tasks
A1: Task ID | B1: Project ID | C1: Title | D1: Description | E1: Supervisor | F1: Site | G1: Status | H1: Priority | I1: Start Date | J1: End Date | K1: Deadline | L1: Status Commentary | M1: Date Completed
A2: T-001 | B2: P-001 | C2: SCE Identification - Completed Facilities | D2: Facilities where P&IDs are well-documented in SDKs and SCE identification has been completed. | E2: Kurt MacKay | F2: Multiple | G2: Completed | H2: 1 | I2: 45689 | J2: 46081 | K2: 46081 | L2: Majority of facilities completed. P&IDs were available in SDKs for these sites. | M2: 46081
A3: T-002 | B3: P-001 | C3: SCE Identification - Harmattan & EEEP | D3: Harmattan and EEEP SDKs do not outline P&IDs for each tag, requiring alternative approaches to identify SCEs. | E3: Kurt MacKay | F3: Harmattan / EEEP | G3: In Progress | H3: 1 | I3: 46037 | K3: 46112 | L3: SDKs for Harmattan and EEEP lack P&ID references per tag. Attempting alternative tag-to-SCE mapping approaches. | N3: 46106
A4: T-003 | B4: P-001 | C4: Maximo Tag Matching | D4: Cross-reference identified SCE tags against the Maximo asset management database to validate equipment records. | E4: Kurt MacKay | F4: All | G4: In Progress | H4: 2 | I4: 45931 | K4: 46112 | L4: Currently matching approximately 45% of tags to Maximo. Discrepancies in naming conventions and missing assets are the main blockers. | N4: 46106
A5: T-004 | B5: P-001 | C5: SCE - On-Hold Facilities (PSGP-1 Dimsdale & Townsend) | D5: SCE work paused for PSGP-1 Dimsdale and Townsend pending completion of their SDK validation processes. | E5: Kurt MacKay | F5: PSGP-1 Dimsdale / Townsend | G5: On Hold | H5: 4 | I5: 45809 | K5: 46203 | L5: Both facilities are currently undergoing SDK validation. SCE identification will resume once validated SDKs are available.
A6: T-005 | B6: P-001 | C6: SCE Site Review Meetings | D6: Present SCE findings to each facility site team and discuss action items. | E6: Kurt MacKay | F6: All | G6: Not Started | H6: 2 | I6: 46113 | K6: 46203 | L6: Target: complete site discussions by end of June. | N6: 46109
A7: T-006 | B7: P-002 | C7: BAHX Technical Analysis | D7: Perform the full engineering analysis of BAHX units - operating conditions, failure modes, inspection history, and risk ranking. | E7: Kurt MacKay | F7: Multiple | G7: Completed | H7: 1 | I7: 45962 | J7: 46096 | K7: 46096 | L7: Analysis complete. All BAHX units evaluated for operating envelope, failure risk, and inspection history. | M7: 46096
A8: T-007 | B8: P-002 | C8: BAHX Final Report | D8: Compile the BAHX study into a formal engineering report documenting methodology, findings, and recommendations. | E8: Kurt MacKay | F8: N/A | G8: In Progress | H8: 1 | I8: 46082 | K8: 46127 | L8: Report approximately 80% complete. Compiling final sections. | N8: 46107
A9: T-008 | B9: P-002 | C9: BAHX Presentation | D9: Create a summary presentation to accompany the BAHX report for management and site teams. | E9: Kurt MacKay | F9: N/A | G9: In Progress | H9: 2 | I9: 46101 | K9: 46132 | L9: Presentation started. Working in parallel with report finalization. | N9: 46108
A10: T-009 | B10: P-002 | C10: BAHX SOP Review | D10: Review facility SOPs for BAHX units to identify any existing operational notes, restrictions, or cautions. | E10: Kurt MacKay | F10: Multiple | G10: In Progress | H10: 3 | I10: 46096 | K10: 46122 | L10: Waiting on SOPs for BAHX units to review for any existing comments or operational notes. | N10: 46106
A11: T-010 | B11: P-002 | C11: BAHX Vendor Meeting - April 1 | D11: Meet with BAHX vendor to learn about replacement unit cost, lead times, and available configurations. | E11: Kurt MacKay | F11: N/A | G11: In Progress | H11: 2 | I11: 46101 | K11: 46113 | L11: Vendor meeting scheduled for April 1st. | N11: 46107
A12: T-011 | B12: P-003 | C12: Dashboard Development & Deployment | D12: Build and deploy the Power BI corrosion coupon dashboard with all facility data. | E12: Kurt MacKay | F12: All | G12: Completed | H12: 2 | I12: 45901 | J12: 46096 | K12: 46096 | L12: Dashboard built, deployed, and in use. Historical data loaded. | M12: 46096
A13: T-012 | B13: P-003 | C13: Auto-Triggered Email Data Pipeline | D13: Create an automated pipeline that ingests new corrosion coupon data from emailed reports and loads it into the dashboard. | E13: Kurt MacKay | F13: N/A | G13: Not Started | H13: 2 | I13: 46113 | K13: 46234 | N13: 46110
A14: T-013 | B14: P-003 | C14: Corrosion Dashboard Handoff Documentation | D14: Create comprehensive documentation for the dashboard and pipeline to enable handoff to the next owner. | E14: Kurt MacKay | F14: N/A | G14: Not Started | H14: 3 | I14: 46218 | K14: 46265 | N14: 46108
A15: T-014 | B15: P-004 | C15: Inspection Scope Tool - Development | D15: Build and deploy the tool that automates the creation of inspection scopes. | E15: Kurt MacKay | F15: N/A | G15: Completed | H15: 2 | I15: 45809 | J15: 46081 | K15: 46081 | L15: Tool is complete and currently in active use. | M15: 46081
A16: T-015 | B16: P-004 | C16: Inspection Scope Tool - Handoff Documentation | D16: Create documentation so the tool can be maintained and used after handoff. | E16: Kurt MacKay | F16: N/A | G16: Not Started | H16: 3 | I16: 46106 | K16: 46142 | N16: 46107
A17: T-016 | B17: P-005 | C17: PI Vision Screen Cleanup - Units, Tags, and Navigation | D17: Review and correct units, tag configuration, and navigation links on all 722 PI Vision screens. Low priority; worked on during downtime. | E17: Dustin MacDonald | F17: All | G17: Ongoing | H17: 5 | L17: Very low priority. Worked on only during downtime. 722 screens total. | N17: 46107
A18: T-017 | B18: P-006 | C18: AI & Python Applications - Exploration & Prototyping | D18: Evaluate AI and Python tools for SOP automation, PI data analysis, and general workflow improvements. | E18: Self-Directed | F18: N/A | G18: Ongoing | H18: 5 | L18: Low priority, self-directed. Worked on during downtime. | N18: 46106

Sheet Deliverables
A1: Deliverable ID | B1: Task ID | C1: Title | D1: Description | E1: Status | F1: Start Date | G1: End Date | H1: Deadline | I1: % Complete
A2: D-001 | B2: T-001 | C2: Collect SDKs and P&IDs for all facilities | D2: Gather Safety Data Knowledge packages and P&ID drawings for every facility in scope. | E2: Completed | F2: 45689 | G2: 45731 | H2: 45731 | I2: 100
A3: D-002 | B3: T-001 | C3: Define SCE identification methodology and criteria | D3: Establish the criteria for classifying an element as safety-critical based on industry standards and AltaGas policies. | E3: Completed | F3: 45703 | G3: 45746 | H3: 45746 | I3: 100
A4: D-003 | B4: T-001 | C4: Complete SCE identification for well-documented facilities | D4: Walk through P&IDs, identify all SCEs, and log each element per facility. | E4: Completed | F4: 45748 | G4: 46022 | H4: 46022 | I4: 100
A5: D-004 | B5: T-001 | C5: Build SCE master register for completed facilities | D5: Compile all identified SCEs into a structured register with tag numbers, descriptions, and facility assignments. | E5: Completed | F5: 45931 | G5: 46053 | H5: 46053 | I5: 100
A6: D-005 | B6: T-002 | C6: Assess Harmattan SDK gaps - identify missing P&ID references | D6: Catalog which tags in the Harmattan SDK lack P&ID cross-references and determine scope of the gap. | E6: Completed | F6: 46037 | G6: 46068 | H6: 46068 | I6: 100
A7: D-006 | B7: T-002 | C7: Assess EEEP SDK gaps - identify missing P&ID references | D7: Catalog which tags in the EEEP SDK lack P&ID cross-references and determine scope of the gap. | E7: Completed | F7: 46054 | G7: 46081 | H7: 46081 | I7: 100
A8: D-007 | B8: T-002 | C8: Develop alternative mapping approach for tag-to-SCE identification | D8: Create a methodology to identify SCEs at sites where SDKs do not map tags to P&IDs directly. | E8: In Progress | F8: 46068 | H8: 46091 | I8: 60
A9: D-008 | B9: T-002 | C9: Complete SCE identification for Harmattan | D9: Apply alternative mapping and complete the SCE register for Harmattan. | E9: In Progress | F9: 46091 | H9: 46106 | I9: 30
A10: D-009 | B10: T-002 | C10: Complete SCE identification for EEEP | D10: Apply alternative mapping and complete the SCE register for EEEP. | E10: In Progress | F10: 46096 | H10: 46112 | I10: 20
A11: D-010 | B11: T-003 | C11: Export Maximo asset database for all facilities | D11: Pull full asset lists from Maximo for every facility in scope. | E11: Completed | F11: 45931 | G11: 45945 | H11: 45945 | I11: 100
A12: D-011 | B12: T-003 | C12: Build tag matching logic and automated comparison | D12: Create matching script/process to compare SCE tag numbers against Maximo records. | E12: Completed | F12: 45945 | G12: 45976 | H12: 45976 | I12: 100
A13: D-012 | B13: T-003 | C13: Run initial match - resolve easy hits (~45% matched) | D13: Execute first matching pass; resolve tags with direct exact matches. | E13: Completed | F13: 45976 | G13: 46081 | H13: 46081 | I13: 100
A14: D-013 | B14: T-003 | C14: Investigate and resolve unmatched tags (~55% remaining) | D14: Manually review remaining unmatched tags - naming discrepancies, missing Maximo entries, decommissioned equipment. | E14: In Progress | F14: 46082 | H14: 46106 | I14: 20
A15: D-014 | B15: T-003 | C15: Produce final Maximo match report with gap summary | D15: Document match rate, root causes of mismatches, and recommended Maximo updates. | E15: Not Started | F15: 46101 | H15: 46112 | I15: 0
A16: D-015 | B16: T-004 | C16: Monitor PSGP-1 Dimsdale SDK validation progress | D16: Track SDK validation status; confirm when validated SDK is available for SCE work. | E16: On Hold | F16: 46082 | H16: 46157 | I16: 0
A17: D-016 | B17: T-004 | C17: Monitor Townsend SDK validation progress | D17: Track SDK validation status for Townsend; confirm when validated SDK is ready. | E17: On Hold | F17: 46082 | H17: 46157 | I17: 0
A18: D-017 | B18: T-004 | C18: Complete SCE identification for PSGP-1 Dimsdale | D18: Once SDK is validated, perform full SCE identification using the confirmed P&IDs. | E18: Not Started | H18: 46188 | I18: 0
A19: D-018 | B19: T-004 | C19: Complete SCE identification for Townsend | D19: Once SDK is validated, perform full SCE identification using the confirmed P&IDs. | E19: Not Started | H19: 46203 | I19: 0
A20: D-019 | B20: T-005 | C20: Prepare site-specific SCE summary packages | D20: Create a per-facility SCE summary with tag lists, Maximo match rates, and gap analysis. | E20: Not Started | F20: 46113 | H20: 46127 | I20: 0
A21: D-020 | B21: T-005 | C21: Schedule and conduct site review meetings | D21: Coordinate with site leads to schedule and hold review meetings for all completed facilities. | E21: Not Started | F21: 46127 | H21: 46188 | I21: 0
A22: D-021 | B22: T-005 | C22: Document action items and findings from site meetings | D22: Capture feedback, corrective actions, and follow-up items from each site review. | E22: Not Started | F22: 46143 | H22: 46203 | I22: 0
A23: D-022 | B23: T-006 | C23: Collect BAHX operating data and inspection records | D23: Gather design datasheets, operating parameters, and historical inspection reports for all BAHX units. | E23: Completed | F23: 45962 | G23: 46006 | H23: 46006 | I23: 100
A24: D-023 | B24: T-006 | C24: Identify failure modes and risk factors | D24: Evaluate common BAHX failure mechanisms (mercury embrittlement, thermal shock, fouling, corrosion) and apply to each unit. | E24: Completed | F24: 46006 | G24: 46053 | H24: 46053 | I24: 100
A25: D-024 | B25: T-006 | C25: Complete risk ranking of all BAHX units | D25: Rank each BAHX unit by risk based on operating conditions, age, inspection findings, and failure mode applicability. | E25: Completed | F25: 46037 | G25: 46081 | H25: 46081 | I25: 100
A26: D-025 | B26: T-006 | C26: Finalize analysis conclusions and recommendations | D26: Summarize findings and develop recommended actions for each unit. | E26: Completed | F26: 46081 | G26: 46096 | H26: 46096 | I26: 100
A27: D-026 | B27: T-007 | C27: Draft report - methodology, scope, and background | D27: Write introductory sections covering the study scope, BAHX background, and methodology. | E27: Completed | F27: 46082 | G27: 46091 | H27: 46091 | I27: 100
A28: D-027 | B28: T-007 | C28: Draft report - analysis results and risk rankings | D28: Write the core technical sections presenting per-unit findings and risk rankings. | E28: Completed | F28: 46091 | G28: 46101 | H28: 46101 | I28: 100
A29: D-028 | B29: T-007 | C29: Draft report - recommendations and action plan | D29: Write the recommendations section with proposed inspection, monitoring, and replacement actions. | E29: In Progress | F29: 46101 | H29: 46109 | I29: 60
A30: D-029 | B30: T-007 | C30: Incorporate vendor cost and lead-time data (post Apr 1 meeting) | D30: After the April 1st vendor meeting, add replacement unit cost and lead-time info to the report. | E30: Not Started | F30: 46113 | H30: 46119 | I30: 0
A31: D-030 | B31: T-007 | C31: Final review, formatting, and report submission | D31: Proofread, format per AltaGas standards, and submit the final BAHX report. | E31: Not Started | F31: 46119 | H31: 46127 | I31: 0
A32: D-031 | B32: T-008 | C32: Outline presentation structure and key messages | D32: Define slide flow: background, methodology, key findings, risk rankings, recommendations. | E32: In Progress | F32: 46101 | H32: 46106 | I32: 50
A33: D-032 | B33: T-008 | C33: Draft presentation slides | D33: Build all slides with data, charts, and summary tables from the report. | E33: Not Started | F33: 46106 | H33: 46122 | I33: 0
A34: D-033 | B34: T-008 | C34: Add vendor cost and lead-time slides (post Apr 1 meeting) | D34: After the vendor meeting, add replacement cost and timeline slides. | E34: Not Started | F34: 46113 | H34: 46124 | I34: 0
A35: D-034 | B35: T-008 | C35: Finalize and review presentation | D35: Polish visuals, review with supervisor, and finalize for delivery. | E35: Not Started | F35: 46124 | H35: 46132 | I35: 0
A36: D-035 | B36: T-009 | C36: Request SOPs for all BAHX-equipped facilities | D36: Contact operations/document control to obtain current SOPs covering BAHX units. | E36: Completed | F36: 46096 | G36: 46101 | H36: 46101 | I36: 100
A37: D-036 | B37: T-009 | C37: Review SOPs for BAHX-related comments and restrictions | D37: Read through received SOPs and extract any operational notes, startup/shutdown cautions, or maintenance remarks about BAHX units. | E37: Not Started | F37: 46106 | H37: 46117 | I37: 0
A38: D-037 | B38: T-009 | C38: Incorporate SOP findings into BAHX report | D38: Add any relevant SOP observations to the final report and recommendations. | E38: Not Started | F38: 46117 | H38: 46122 | I38: 0
A39: D-038 | B39: T-010 | C39: Prepare BAHX unit specs and questions for vendor | D39: Compile the specs of current BAHX units and prepare a list of questions about cost, lead time, and replacement options. | E39: In Progress | F39: 46101 | H39: 46109 | I39: 30
A40: D-039 | B40: T-010 | C40: Attend vendor meeting and capture notes | D40: Attend the April 1st meeting; record cost quotes, lead times, and configuration options. | E40: Not Started | F40: 46113 | H40: 46113 | I40: 0
...

Sheet Timelines
A1: Item ID | B1: Item Type | C1: Title | D1: Parent ID | E1: Start Date | F1: Duration (days) | G1: End Date | H1: Deadline | I1: Status | J1: % Complete | K1: Time Allocated | L1: Time Spent | M1: Scheduled Date | N1: Milestones
A2: P-001 | B2: Project | C2: =IFERROR(VLOOKUP($A2,'Projects'!$A:$M,2,FALSE),"") | E2: =IFERROR(VLOOKUP($A2,'Projects'!$A:$M,9,FALSE),"") | F2: =IFERROR(IF(F2="","",G2-F2),"") | G2: =IFERROR(VLOOKUP($A2,'Projects'!$A:$M,10,FALSE),"") | H2: =IFERROR(VLOOKUP($A2,'Projects'!$A:$M,11,FALSE),"") | I2: =IFERROR(VLOOKUP($A2,'Projects'!$A:$M,7,FALSE),"")
A3: P-002 | B3: Project | C3: =IFERROR(VLOOKUP($A3,'Projects'!$A:$M,2,FALSE),"") | E3: =IFERROR(VLOOKUP($A3,'Projects'!$A:$M,9,FALSE),"") | F3: =IFERROR(IF(F3="","",G3-F3),"") | G3: =IFERROR(VLOOKUP($A3,'Projects'!$A:$M,10,FALSE),"") | H3: =IFERROR(VLOOKUP($A3,'Projects'!$A:$M,11,FALSE),"") | I3: =IFERROR(VLOOKUP($A3,'Projects'!$A:$M,7,FALSE),"")
A4: P-003 | B4: Project | C4: =IFERROR(VLOOKUP($A4,'Projects'!$A:$M,2,FALSE),"") | E4: =IFERROR(VLOOKUP($A4,'Projects'!$A:$M,9,FALSE),"") | F4: =IFERROR(IF(F4="","",G4-F4),"") | G4: =IFERROR(VLOOKUP($A4,'Projects'!$A:$M,10,FALSE),"") | H4: =IFERROR(VLOOKUP($A4,'Projects'!$A:$M,11,FALSE),"") | I4: =IFERROR(VLOOKUP($A4,'Projects'!$A:$M,7,FALSE),"")
A5: P-004 | B5: Project | C5: =IFERROR(VLOOKUP($A5,'Projects'!$A:$M,2,FALSE),"") | E5: =IFERROR(VLOOKUP($A5,'Projects'!$A:$M,9,FALSE),"") | F5: =IFERROR(IF(F5="","",G5-F5),"") | G5: =IFERROR(VLOOKUP($A5,'Projects'!$A:$M,10,FALSE),"") | H5: =IFERROR(VLOOKUP($A5,'Projects'!$A:$M,11,FALSE),"") | I5: =IFERROR(VLOOKUP($A5,'Projects'!$A:$M,7,FALSE),"")
A6: P-005 | B6: Project | C6: =IFERROR(VLOOKUP($A6,'Projects'!$A:$M,2,FALSE),"") | E6: =IFERROR(VLOOKUP($A6,'Projects'!$A:$M,9,FALSE),"") | F6: =IFERROR(IF(F6="","",G6-F6),"") | G6: =IFERROR(VLOOKUP($A6,'Projects'!$A:$M,10,FALSE),"") | H6: =IFERROR(VLOOKUP($A6,'Projects'!$A:$M,11,FALSE),"") | I6: =IFERROR(VLOOKUP($A6,'Projects'!$A:$M,7,FALSE),"")
A7: P-006 | B7: Project | C7: =IFERROR(VLOOKUP($A7,'Projects'!$A:$M,2,FALSE),"") | E7: =IFERROR(VLOOKUP($A7,'Projects'!$A:$M,9,FALSE),"") | F7: =IFERROR(IF(F7="","",G7-F7),"") | G7: =IFERROR(VLOOKUP($A7,'Projects'!$A:$M,10,FALSE),"") | H7: =IFERROR(VLOOKUP($A7,'Projects'!$A:$M,11,FALSE),"") | I7: =IFERROR(VLOOKUP($A7,'Projects'!$A:$M,7,FALSE),"")
A8: T-001 | B8: Task | C8: =IFERROR(VLOOKUP($A8,'Tasks'!$A:$N,3,FALSE),"") | D8: =IFERROR(VLOOKUP($A8,'Tasks'!$A:$N,2,FALSE),"") | E8: =IFERROR(VLOOKUP($A8,'Tasks'!$A:$N,9,FALSE),"") | F8: =IFERROR(IF(F8="","",G8-F8),"") | G8: =IFERROR(VLOOKUP($A8,'Tasks'!$A:$N,10,FALSE),"") | H8: =IFERROR(VLOOKUP($A8,'Tasks'!$A:$N,11,FALSE),"") | I8: =IFERROR(VLOOKUP($A8,'Tasks'!$A:$N,7,FALSE),"") | M8: =IFERROR(VLOOKUP($A8,'Tasks'!$A:$N,14,FALSE),"")
A9: T-002 | B9: Task | C9: =IFERROR(VLOOKUP($A9,'Tasks'!$A:$N,3,FALSE),"") | D9: =IFERROR(VLOOKUP($A9,'Tasks'!$A:$N,2,FALSE),"") | E9: =IFERROR(VLOOKUP($A9,'Tasks'!$A:$N,9,FALSE),"") | F9: =IFERROR(IF(F9="","",G9-F9),"") | G9: =IFERROR(VLOOKUP($A9,'Tasks'!$A:$N,10,FALSE),"") | H9: =IFERROR(VLOOKUP($A9,'Tasks'!$A:$N,11,FALSE),"") | I9: =IFERROR(VLOOKUP($A9,'Tasks'!$A:$N,7,FALSE),"") | M9: =IFERROR(VLOOKUP($A9,'Tasks'!$A:$N,14,FALSE),"")
A10: T-003 | B10: Task | C10: =IFERROR(VLOOKUP($A10,'Tasks'!$A:$N,3,FALSE),"") | D10: =IFERROR(VLOOKUP($A10,'Tasks'!$A:$N,2,FALSE),"") | E10: =IFERROR(VLOOKUP($A10,'Tasks'!$A:$N,9,FALSE),"") | F10: =IFERROR(IF(F10="","",G10-F10),"") | G10: =IFERROR(VLOOKUP($A10,'Tasks'!$A:$N,10,FALSE),"") | H10: =IFERROR(VLOOKUP($A10,'Tasks'!$A:$N,11,FALSE),"") | I10: =IFERROR(VLOOKUP($A10,'Tasks'!$A:$N,7,FALSE),"") | M10: =IFERROR(VLOOKUP($A10,'Tasks'!$A:$N,14,FALSE),"")
A11: T-004 | B11: Task | C11: =IFERROR(VLOOKUP($A11,'Tasks'!$A:$N,3,FALSE),"") | D11: =IFERROR(VLOOKUP($A11,'Tasks'!$A:$N,2,FALSE),"") | E11: =IFERROR(VLOOKUP($A11,'Tasks'!$A:$N,9,FALSE),"") | F11: =IFERROR(IF(F11="","",G11-F11),"") | G11: =IFERROR(VLOOKUP($A11,'Tasks'!$A:$N,10,FALSE),"") | H11: =IFERROR(VLOOKUP($A11,'Tasks'!$A:$N,11,FALSE),"") | I11: =IFERROR(VLOOKUP($A11,'Tasks'!$A:$N,7,FALSE),"") | M11: =IFERROR(VLOOKUP($A11,'Tasks'!$A:$N,14,FALSE),"")
A12: T-005 | B12: Task | C12: =IFERROR(VLOOKUP($A12,'Tasks'!$A:$N,3,FALSE),"") | D12: =IFERROR(VLOOKUP($A12,'Tasks'!$A:$N,2,FALSE),"") | E12: =IFERROR(VLOOKUP($A12,'Tasks'!$A:$N,9,FALSE),"") | F12: =IFERROR(IF(F12="","",G12-F12),"") | G12: =IFERROR(VLOOKUP($A12,'Tasks'!$A:$N,10,FALSE),"") | H12: =IFERROR(VLOOKUP($A12,'Tasks'!$A:$N,11,FALSE),"") | I12: =IFERROR(VLOOKUP($A12,'Tasks'!$A:$N,7,FALSE),"") | M12: =IFERROR(VLOOKUP($A12,'Tasks'!$A:$N,14,FALSE),"")
A13: T-006 | B13: Task | C13: =IFERROR(VLOOKUP($A13,'Tasks'!$A:$N,3,FALSE),"") | D13: =IFERROR(VLOOKUP($A13,'Tasks'!$A:$N,2,FALSE),"") | E13: =IFERROR(VLOOKUP($A13,'Tasks'!$A:$N,9,FALSE),"") | F13: =IFERROR(IF(F13="","",G13-F13),"") | G13: =IFERROR(VLOOKUP($A13,'Tasks'!$A:$N,10,FALSE),"") | H13: =IFERROR(VLOOKUP($A13,'Tasks'!$A:$N,11,FALSE),"") | I13: =IFERROR(VLOOKUP($A13,'Tasks'!$A:$N,7,FALSE),"") | M13: =IFERROR(VLOOKUP($A13,'Tasks'!$A:$N,14,FALSE),"")
A14: T-007 | B14: Task | C14: =IFERROR(VLOOKUP($A14,'Tasks'!$A:$N,3,FALSE),"") | D14: =IFERROR(VLOOKUP($A14,'Tasks'!$A:$N,2,FALSE),"") | E14: =IFERROR(VLOOKUP($A14,'Tasks'!$A:$N,9,FALSE),"") | F14: =IFERROR(IF(F14="","",G14-F14),"") | G14: =IFERROR(VLOOKUP($A14,'Tasks'!$A:$N,10,FALSE),"") | H14: =IFERROR(VLOOKUP($A14,'Tasks'!$A:$N,11,FALSE),"") | I14: =IFERROR(VLOOKUP($A14,'Tasks'!$A:$N,7,FALSE),"") | M14: =IFERROR(VLOOKUP($A14,'Tasks'!$A:$N,14,FALSE),"")
A15: T-008 | B15: Task | C15: =IFERROR(VLOOKUP($A15,'Tasks'!$A:$N,3,FALSE),"") | D15: =IFERROR(VLOOKUP($A15,'Tasks'!$A:$N,2,FALSE),"") | E15: =IFERROR(VLOOKUP($A15,'Tasks'!$A:$N,9,FALSE),"") | F15: =IFERROR(IF(F15="","",G15-F15),"") | G15: =IFERROR(VLOOKUP($A15,'Tasks'!$A:$N,10,FALSE),"") | H15: =IFERROR(VLOOKUP($A15,'Tasks'!$A:$N,11,FALSE),"") | I15: =IFERROR(VLOOKUP($A15,'Tasks'!$A:$N,7,FALSE),"") | M15: =IFERROR(VLOOKUP($A15,'Tasks'!$A:$N,14,FALSE),"")
A16: T-009 | B16: Task | C16: =IFERROR(VLOOKUP($A16,'Tasks'!$A:$N,3,FALSE),"") | D16: =IFERROR(VLOOKUP($A16,'Tasks'!$A:$N,2,FALSE),"") | E16: =IFERROR(VLOOKUP($A16,'Tasks'!$A:$N,9,FALSE),"") | F16: =IFERROR(IF(F16="","",G16-F16),"") | G16: =IFERROR(VLOOKUP($A16,'Tasks'!$A:$N,10,FALSE),"") | H16: =IFERROR(VLOOKUP($A16,'Tasks'!$A:$N,11,FALSE),"") | I16: =IFERROR(VLOOKUP($A16,'Tasks'!$A:$N,7,FALSE),"") | M16: =IFERROR(VLOOKUP($A16,'Tasks'!$A:$N,14,FALSE),"")
A17: T-010 | B17: Task | C17: =IFERROR(VLOOKUP($A17,'Tasks'!$A:$N,3,FALSE),"") | D17: =IFERROR(VLOOKUP($A17,'Tasks'!$A:$N,2,FALSE),"") | E17: =IFERROR(VLOOKUP($A17,'Tasks'!$A:$N,9,FALSE),"") | F17: =IFERROR(IF(F17="","",G17-F17),"") | G17: =IFERROR(VLOOKUP($A17,'Tasks'!$A:$N,10,FALSE),"") | H17: =IFERROR(VLOOKUP($A17,'Tasks'!$A:$N,11,FALSE),"") | I17: =IFERROR(VLOOKUP($A17,'Tasks'!$A:$N,7,FALSE),"") | M17: =IFERROR(VLOOKUP($A17,'Tasks'!$A:$N,14,FALSE),"")
A18: T-011 | B18: Task | C18: =IFERROR(VLOOKUP($A18,'Tasks'!$A:$N,3,FALSE),"") | D18: =IFERROR(VLOOKUP($A18,'Tasks'!$A:$N,2,FALSE),"") | E18: =IFERROR(VLOOKUP($A18,'Tasks'!$A:$N,9,FALSE),"") | F18: =IFERROR(IF(F18="","",G18-F18),"") | G18: =IFERROR(VLOOKUP($A18,'Tasks'!$A:$N,10,FALSE),"") | H18: =IFERROR(VLOOKUP($A18,'Tasks'!$A:$N,11,FALSE),"") | I18: =IFERROR(VLOOKUP($A18,'Tasks'!$A:$N,7,FALSE),"") | M18: =IFERROR(VLOOKUP($A18,'Tasks'!$A:$N,14,FALSE),"")
A19: T-012 | B19: Task | C19: =IFERROR(VLOOKUP($A19,'Tasks'!$A:$N,3,FALSE),"") | D19: =IFERROR(VLOOKUP($A19,'Tasks'!$A:$N,2,FALSE),"") | E19: =IFERROR(VLOOKUP($A19,'Tasks'!$A:$N,9,FALSE),"") | F19: =IFERROR(IF(F19="","",G19-F19),"") | G19: =IFERROR(VLOOKUP($A19,'Tasks'!$A:$N,10,FALSE),"") | H19: =IFERROR(VLOOKUP($A19,'Tasks'!$A:$N,11,FALSE),"") | I19: =IFERROR(VLOOKUP($A19,'Tasks'!$A:$N,7,FALSE),"") | M19: =IFERROR(VLOOKUP($A19,'Tasks'!$A:$N,14,FALSE),"")
... A24: T-017 | B24: Task | C24: =IFERROR(VLOOKUP($A24,'Tasks'!$A:$N,3,FALSE),"") | D24: =IFERROR(VLOOKUP($A24,'Tasks'!$A:$N,2,FALSE),"") | E24: =IFERROR(VLOOKUP($A24,'Tasks'!$A:$N,9,FALSE),"") | F24: =IFERROR(IF(F24="","",G24-F24),"") | G24: =IFERROR(VLOOKUP($A24,'Tasks'!$A:$N,10,FALSE),"") | H24: =IFERROR(VLOOKUP($A24,'Tasks'!$A:$N,11,FALSE),"") | I24: =IFERROR(VLOOKUP($A24,'Tasks'!$A:$N,7,FALSE),"") | M24: =IFERROR(VLOOKUP($A24,'Tasks'!$A:$N,14,FALSE),"")
A25: D-001 | B25: Deliverable | C25: =IFERROR(VLOOKUP($A25,'Deliverables'!$A:$K,3,FALSE),"") | D25: =IFERROR(VLOOKUP($A25,'Deliverables'!$A:$K,2,FALSE),"") | E25: =IFERROR(VLOOKUP($A25,'Deliverables'!$A:$K,6,FALSE),"") | F25: =IFERROR(IF(F25="","",G25-F25),"") | G25: =IFERROR(VLOOKUP($A25,'Deliverables'!$A:$K,7,FALSE),"") | H25: =IFERROR(VLOOKUP($A25,'Deliverables'!$A:$K,8,FALSE),"") | I25: =IFERROR(VLOOKUP($A25,'Deliverables'!$A:$K,5,FALSE),"") | J25: =IFERROR(VLOOKUP($A25,'Deliverables'!$A:$K,9,FALSE),"") | K25: =IFERROR(VLOOKUP($A25,'Deliverables'!$A:$K,10,FALSE),"") | L25: =IFERROR(VLOOKUP($A25,'Deliverables'!$A:$K,11,FALSE),"")
A26: D-002 | B26: Deliverable | C26: =IFERROR(VLOOKUP($A26,'Deliverables'!$A:$K,3,FALSE),"") | D26: =IFERROR(VLOOKUP($A26,'Deliverables'!$A:$K,2,FALSE),"") | E26: =IFERROR(VLOOKUP($A26,'Deliverables'!$A:$K,6,FALSE),"") | F26: =IFERROR(IF(F26="","",G26-F26),"") | G26: =IFERROR(VLOOKUP($A26,'Deliverables'!$A:$K,7,FALSE),"") | H26: =IFERROR(VLOOKUP($A26,'Deliverables'!$A:$K,8,FALSE),"") | I26: =IFERROR(VLOOKUP($A26,'Deliverables'!$A:$K,5,FALSE),"") | J26: =IFERROR(VLOOKUP($A26,'Deliverables'!$A:$K,9,FALSE),"") | K26: =IFERROR(VLOOKUP($A26,'Deliverables'!$A:$K,10,FALSE),"") | L26: =IFERROR(VLOOKUP($A26,'Deliverables'!$A:$K,11,FALSE),"")
A27: D-003 | B27: Deliverable | C27: =IFERROR(VLOOKUP($A27,'Deliverables'!$A:$K,3,FALSE),"") | D27: =IFERROR(VLOOKUP($A27,'Deliverables'!$A:$K,2,FALSE),"") | E27: =IFERROR(VLOOKUP($A27,'Deliverables'!$A:$K,6,FALSE),"") | F27: =IFERROR(IF(F27="","",G27-F27),"") | G27: =IFERROR(VLOOKUP($A27,'Deliverables'!$A:$K,7,FALSE),"") | H27: =IFERROR(VLOOKUP($A27,'Deliverables'!$A:$K,8,FALSE),"") | I27: =IFERROR(VLOOKUP($A27,'Deliverables'!$A:$K,5,FALSE),"") | J27: =IFERROR(VLOOKUP($A27,'Deliverables'!$A:$K,9,FALSE),"") | K27: =IFERROR(VLOOKUP($A27,'Deliverables'!$A:$K,10,FALSE),"") | L27: =IFERROR(VLOOKUP($A27,'Deliverables'!$A:$K,11,FALSE),"")
A28: D-004 | B28: Deliverable | C28: =IFERROR(VLOOKUP($A28,'Deliverables'!$A:$K,3,FALSE),"") | D28: =IFERROR(VLOOKUP($A28,'Deliverables'!$A:$K,2,FALSE),"") | E28: =IFERROR(VLOOKUP($A28,'Deliverables'!$A:$K,6,FALSE),"") | F28: =IFERROR(IF(F28="","",G28-F28),"") | G28: =IFERROR(VLOOKUP($A28,'Deliverables'!$A:$K,7,FALSE),"") | H28: =IFERROR(VLOOKUP($A28,'Deliverables'!$A:$K,8,FALSE),"") | I28: =IFERROR(VLOOKUP($A28,'Deliverables'!$A:$K,5,FALSE),"") | J28: =IFERROR(VLOOKUP($A28,'Deliverables'!$A:$K,9,FALSE),"") | K28: =IFERROR(VLOOKUP($A28,'Deliverables'!$A:$K,10,FALSE),"") | L28: =IFERROR(VLOOKUP($A28,'Deliverables'!$A:$K,11,FALSE),"")
A29: D-005 | B29: Deliverable | C29: =IFERROR(VLOOKUP($A29,'Deliverables'!$A:$K,3,FALSE),"") | D29: =IFERROR(VLOOKUP($A29,'Deliverables'!$A:$K,2,FALSE),"") | E29: =IFERROR(VLOOKUP($A29,'Deliverables'!$A:$K,6,FALSE),"") | F29: =IFERROR(IF(F29="","",G29-F29),"") | G29: =IFERROR(VLOOKUP($A29,'Deliverables'!$A:$K,7,FALSE),"") | H29: =IFERROR(VLOOKUP($A29,'Deliverables'!$A:$K,8,FALSE),"") | I29: =IFERROR(VLOOKUP($A29,'Deliverables'!$A:$K,5,FALSE),"") | J29: =IFERROR(VLOOKUP($A29,'Deliverables'!$A:$K,9,FALSE),"") | K29: =IFERROR(VLOOKUP($A29,'Deliverables'!$A:$K,10,FALSE),"") | L29: =IFERROR(VLOOKUP($A29,'Deliverables'!$A:$K,11,FALSE),"")
A30: D-006 | B30: Deliverable | C30: =IFERROR(VLOOKUP($A30,'Deliverables'!$A:$K,3,FALSE),"") | D30: =IFERROR(VLOOKUP($A30,'Deliverables'!$A:$K,2,FALSE),"") | E30: =IFERROR(VLOOKUP($A30,'Deliverables'!$A:$K,6,FALSE),"") | F30: =IFERROR(IF(F30="","",G30-F30),"") | G30: =IFERROR(VLOOKUP($A30,'Deliverables'!$A:$K,7,FALSE),"") | H30: =IFERROR(VLOOKUP($A30,'Deliverables'!$A:$K,8,FALSE),"") | I30: =IFERROR(VLOOKUP($A30,'Deliverables'!$A:$K,5,FALSE),"") | J30: =IFERROR(VLOOKUP($A30,'Deliverables'!$A:$K,9,FALSE),"") | K30: =IFERROR(VLOOKUP($A30,'Deliverables'!$A:$K,10,FALSE),"") | L30: =IFERROR(VLOOKUP($A30,'Deliverables'!$A:$K,11,FALSE),"")
A31: D-007 | B31: Deliverable | C31: =IFERROR(VLOOKUP($A31,'Deliverables'!$A:$K,3,FALSE),"") | D31: =IFERROR(VLOOKUP($A31,'Deliverables'!$A:$K,2,FALSE),"") | E31: =IFERROR(VLOOKUP($A31,'Deliverables'!$A:$K,6,FALSE),"") | F31: =IFERROR(IF(F31="","",G31-F31),"") | G31: =IFERROR(VLOOKUP($A31,'Deliverables'!$A:$K,7,FALSE),"") | H31: =IFERROR(VLOOKUP($A31,'Deliverables'!$A:$K,8,FALSE),"") | I31: =IFERROR(VLOOKUP($A31,'Deliverables'!$A:$K,5,FALSE),"") | J31: =IFERROR(VLOOKUP($A31,'Deliverables'!$A:$K,9,FALSE),"") | K31: =IFERROR(VLOOKUP($A31,'Deliverables'!$A:$K,10,FALSE),"") | L31: =IFERROR(VLOOKUP($A31,'Deliverables'!$A:$K,11,FALSE),"")
A32: D-008 | B32: Deliverable | C32: =IFERROR(VLOOKUP($A32,'Deliverables'!$A:$K,3,FALSE),"") | D32: =IFERROR(VLOOKUP($A32,'Deliverables'!$A:$K,2,FALSE),"") | E32: =IFERROR(VLOOKUP($A32,'Deliverables'!$A:$K,6,FALSE),"") | F32: =IFERROR(IF(F32="","",G32-F32),"") | G32: =IFERROR(VLOOKUP($A32,'Deliverables'!$A:$K,7,FALSE),"") | H32: =IFERROR(VLOOKUP($A32,'Deliverables'!$A:$K,8,FALSE),"") | I32: =IFERROR(VLOOKUP($A32,'Deliverables'!$A:$K,5,FALSE),"") | J32: =IFERROR(VLOOKUP($A32,'Deliverables'!$A:$K,9,FALSE),"") | K32: =IFERROR(VLOOKUP($A32,'Deliverables'!$A:$K,10,FALSE),"") | L32: =IFERROR(VLOOKUP($A32,'Deliverables'!$A:$K,11,FALSE),"")
A33: D-009 | B33: Deliverable | C33: =IFERROR(VLOOKUP($A33,'Deliverables'!$A:$K,3,FALSE),"") | D33: =IFERROR(VLOOKUP($A33,'Deliverables'!$A:$K,2,FALSE),"") | E33: =IFERROR(VLOOKUP($A33,'Deliverables'!$A:$K,6,FALSE),"") | F33: =IFERROR(IF(F33="","",G33-F33),"") | G33: =IFERROR(VLOOKUP($A33,'Deliverables'!$A:$K,7,FALSE),"") | H33: =IFERROR(VLOOKUP($A33,'Deliverables'!$A:$K,8,FALSE),"") | I33: =IFERROR(VLOOKUP($A33,'Deliverables'!$A:$K,5,FALSE),"") | J33: =IFERROR(VLOOKUP($A33,'Deliverables'!$A:$K,9,FALSE),"") | K33: =IFERROR(VLOOKUP($A33,'Deliverables'!$A:$K,10,FALSE),"") | L33: =IFERROR(VLOOKUP($A33,'Deliverables'!$A:$K,11,FALSE),"")
A34: D-010 | B34: Deliverable | C34: =IFERROR(VLOOKUP($A34,'Deliverables'!$A:$K,3,FALSE),"") | D34: =IFERROR(VLOOKUP($A34,'Deliverables'!$A:$K,2,FALSE),"") | E34: =IFERROR(VLOOKUP($A34,'Deliverables'!$A:$K,6,FALSE),"") | F34: =IFERROR(IF(F34="","",G34-F34),"") | G34: =IFERROR(VLOOKUP($A34,'Deliverables'!$A:$K,7,FALSE),"") | H34: =IFERROR(VLOOKUP($A34,'Deliverables'!$A:$K,8,FALSE),"") | I34: =IFERROR(VLOOKUP($A34,'Deliverables'!$A:$K,5,FALSE),"") | J34: =IFERROR(VLOOKUP($A34,'Deliverables'!$A:$K,9,FALSE),"") | K34: =IFERROR(VLOOKUP($A34,'Deliverables'!$A:$K,10,FALSE),"") | L34: =IFERROR(VLOOKUP($A34,'Deliverables'!$A:$K,11,FALSE),"")
A35: D-011 | B35: Deliverable | C35: =IFERROR(VLOOKUP($A35,'Deliverables'!$A:$K,3,FALSE),"") | D35: =IFERROR(VLOOKUP($A35,'Deliverables'!$A:$K,2,FALSE),"") | E35: =IFERROR(VLOOKUP($A35,'Deliverables'!$A:$K,6,FALSE),"") | F35: =IFERROR(IF(F35="","",G35-F35),"") | G35: =IFERROR(VLOOKUP($A35,'Deliverables'!$A:$K,7,FALSE),"") | H35: =IFERROR(VLOOKUP($A35,'Deliverables'!$A:$K,8,FALSE),"") | I35: =IFERROR(VLOOKUP($A35,'Deliverables'!$A:$K,5,FALSE),"") | J35: =IFERROR(VLOOKUP($A35,'Deliverables'!$A:$K,9,FALSE),"") | K35: =IFERROR(VLOOKUP($A35,'Deliverables'!$A:$K,10,FALSE),"") | L35: =IFERROR(VLOOKUP($A35,'Deliverables'!$A:$K,11,FALSE),"")
A36: D-012 | B36: Deliverable | C36: =IFERROR(VLOOKUP($A36,'Deliverables'!$A:$K,3,FALSE),"") | D36: =IFERROR(VLOOKUP($A36,'Deliverables'!$A:$K,2,FALSE),"") | E36: =IFERROR(VLOOKUP($A36,'Deliverables'!$A:$K,6,FALSE),"") | F36: =IFERROR(IF(F36="","",G36-F36),"") | G36: =IFERROR(VLOOKUP($A36,'Deliverables'!$A:$K,7,FALSE),"") | H36: =IFERROR(VLOOKUP($A36,'Deliverables'!$A:$K,8,FALSE),"") | I36: =IFERROR(VLOOKUP($A36,'Deliverables'!$A:$K,5,FALSE),"") | J36: =IFERROR(VLOOKUP($A36,'Deliverables'!$A:$K,9,FALSE),"") | K36: =IFERROR(VLOOKUP($A36,'Deliverables'!$A:$K,10,FALSE),"") | L36: =IFERROR(VLOOKUP($A36,'Deliverables'!$A:$K,11,FALSE),"")
... A91: D-067 | B91: Deliverable | C91: =IFERROR(VLOOKUP($A91,'Deliverables'!$A:$K,3,FALSE),"") | D91: =IFERROR(VLOOKUP($A91,'Deliverables'!$A:$K,2,FALSE),"") | E91: =IFERROR(VLOOKUP($A91,'Deliverables'!$A:$K,6,FALSE),"") | F91: =IFERROR(IF(F91="","",G91-F91),"") | G91: =IFERROR(VLOOKUP($A91,'Deliverables'!$A:$K,7,FALSE),"") | H91: =IFERROR(VLOOKUP($A91,'Deliverables'!$A:$K,8,FALSE),"") | I91: =IFERROR(VLOOKUP($A91,'Deliverables'!$A:$K,5,FALSE),"") | J91: =IFERROR(VLOOKUP($A91,'Deliverables'!$A:$K,9,FALSE),"") | K91: =IFERROR(VLOOKUP($A91,'Deliverables'!$A:$K,10,FALSE),"") | L91: =IFERROR(VLOOKUP($A91,'Deliverables'!$A:$K,11,FALSE),"")

Sheet Gantt Chart
A1: Item ID | B1: Title | C1: Start | D1: End | E1: Status | F1: 46099 | G1: 46106 | H1: 46113 | I1: 46120 | J1: 46127 | K1: 46134 | L1: 46141 | M1: 46148 | N1: 46155 | O1: 46162 | P1: 46169 | Q1: 46176 | R1: 46183
A2: P-001 | B2: =IFERROR(VLOOKUP($A2,'Timelines'!$A:$K,3,FALSE),"") | C2: =IFERROR(VLOOKUP($A2,'Timelines'!$A:$K,5,FALSE),"") | D2: =IFERROR(VLOOKUP($A2,'Timelines'!$A:$K,7,FALSE),"") | E2: =IFERROR(VLOOKUP($A2,'Timelines'!$A:$K,9,FALSE),"")
A3: P-002 | B3: =IFERROR(VLOOKUP($A3,'Timelines'!$A:$K,3,FALSE),"") | C3: =IFERROR(VLOOKUP($A3,'Timelines'!$A:$K,5,FALSE),"") | D3: =IFERROR(VLOOKUP($A3,'Timelines'!$A:$K,7,FALSE),"") | E3: =IFERROR(VLOOKUP($A3,'Timelines'!$A:$K,9,FALSE),"")
A4: P-003 | B4: =IFERROR(VLOOKUP($A4,'Timelines'!$A:$K,3,FALSE),"") | C4: =IFERROR(VLOOKUP($A4,'Timelines'!$A:$K,5,FALSE),"") | D4: =IFERROR(VLOOKUP($A4,'Timelines'!$A:$K,7,FALSE),"") | E4: =IFERROR(VLOOKUP($A4,'Timelines'!$A:$K,9,FALSE),"")
A5: P-004 | B5: =IFERROR(VLOOKUP($A5,'Timelines'!$A:$K,3,FALSE),"") | C5: =IFERROR(VLOOKUP($A5,'Timelines'!$A:$K,5,FALSE),"") | D5: =IFERROR(VLOOKUP($A5,'Timelines'!$A:$K,7,FALSE),"") | E5: =IFERROR(VLOOKUP($A5,'Timelines'!$A:$K,9,FALSE),"")
A6: P-005 | B6: =IFERROR(VLOOKUP($A6,'Timelines'!$A:$K,3,FALSE),"") | C6: =IFERROR(VLOOKUP($A6,'Timelines'!$A:$K,5,FALSE),"") | D6: =IFERROR(VLOOKUP($A6,'Timelines'!$A:$K,7,FALSE),"") | E6: =IFERROR(VLOOKUP($A6,'Timelines'!$A:$K,9,FALSE),"")
A7: P-006 | B7: =IFERROR(VLOOKUP($A7,'Timelines'!$A:$K,3,FALSE),"") | C7: =IFERROR(VLOOKUP($A7,'Timelines'!$A:$K,5,FALSE),"") | D7: =IFERROR(VLOOKUP($A7,'Timelines'!$A:$K,7,FALSE),"") | E7: =IFERROR(VLOOKUP($A7,'Timelines'!$A:$K,9,FALSE),"")
A8: T-001 | B8: =IFERROR(VLOOKUP($A8,'Timelines'!$A:$K,3,FALSE),"") | C8: =IFERROR(VLOOKUP($A8,'Timelines'!$A:$K,5,FALSE),"") | D8: =IFERROR(VLOOKUP($A8,'Timelines'!$A:$K,7,FALSE),"") | E8: =IFERROR(VLOOKUP($A8,'Timelines'!$A:$K,9,FALSE),"")
A9: T-002 | B9: =IFERROR(VLOOKUP($A9,'Timelines'!$A:$K,3,FALSE),"") | C9: =IFERROR(VLOOKUP($A9,'Timelines'!$A:$K,5,FALSE),"") | D9: =IFERROR(VLOOKUP($A9,'Timelines'!$A:$K,7,FALSE),"") | E9: =IFERROR(VLOOKUP($A9,'Timelines'!$A:$K,9,FALSE),"")
A10: T-003 | B10: =IFERROR(VLOOKUP($A10,'Timelines'!$A:$K,3,FALSE),"") | C10: =IFERROR(VLOOKUP($A10,'Timelines'!$A:$K,5,FALSE),"") | D10: =IFERROR(VLOOKUP($A10,'Timelines'!$A:$K,7,FALSE),"") | E10: =IFERROR(VLOOKUP($A10,'Timelines'!$A:$K,9,FALSE),"")
A11: T-004 | B11: =IFERROR(VLOOKUP($A11,'Timelines'!$A:$K,3,FALSE),"") | C11: =IFERROR(VLOOKUP($A11,'Timelines'!$A:$K,5,FALSE),"") | D11: =IFERROR(VLOOKUP($A11,'Timelines'!$A:$K,7,FALSE),"") | E11: =IFERROR(VLOOKUP($A11,'Timelines'!$A:$K,9,FALSE),"")
A12: T-005 | B12: =IFERROR(VLOOKUP($A12,'Timelines'!$A:$K,3,FALSE),"") | C12: =IFERROR(VLOOKUP($A12,'Timelines'!$A:$K,5,FALSE),"") | D12: =IFERROR(VLOOKUP($A12,'Timelines'!$A:$K,7,FALSE),"") | E12: =IFERROR(VLOOKUP($A12,'Timelines'!$A:$K,9,FALSE),"")
A13: T-006 | B13: =IFERROR(VLOOKUP($A13,'Timelines'!$A:$K,3,FALSE),"") | C13: =IFERROR(VLOOKUP($A13,'Timelines'!$A:$K,5,FALSE),"") | D13: =IFERROR(VLOOKUP($A13,'Timelines'!$A:$K,7,FALSE),"") | E13: =IFERROR(VLOOKUP($A13,'Timelines'!$A:$K,9,FALSE),"")
... A91: D-067 | B91: =IFERROR(VLOOKUP($A91,'Timelines'!$A:$K,3,FALSE),"") | C91: =IFERROR(VLOOKUP($A91,'Timelines'!$A:$K,5,FALSE),"") | D91: =IFERROR(VLOOKUP($A91,'Timelines'!$A:$K,7,FALSE),"") | E91: =IFERROR(VLOOKUP($A91,'Timelines'!$A:$K,9,FALSE),"")
